Workbook

Sheet Roadmap
A1: StudyLog roadmap
A2: Counts come from the Backlog sheet. Edit only the yellow cells (Timeframe, Target).
A4: Milestone | B4: Name | C4: Goal | D4: Timeframe | E4: Target | F4: Items | G4: Done | H4: In progress | I4: Blocked | J4: Open | K4: % done | L4: Status
A5: M0 | B5: Foundations | C5: API, CLI, tests and the first web pages | D5: Done so far | F5: =COUNTIFS(Backlog!$E$2:$E$500,$A5,Backlog!$J$2:$J$500,"<>Won't do") | G5: =COUNTIFS(Backlog!$E$2:$E$500,$A5,Backlog!$J$2:$J$500,"Done") | H5: =COUNTIFS(Backlog!$E$2:$E$500,$A5,Backlog!$J$2:$J$500,"In progress") | I5: =COUNTIFS(Backlog!$E$2:$E$500,$A5,Backlog!$J$2:$J$500,"Blocked") | J5: =F5-G5 | K5: =IF(F5=0,0,G5/F5) | L5: =IF(F5=0,"Empty",IF(G5=F5,"Done",IF(G5+H5+I5>0,"In progress","Not started")))
A6: M8 | B6: Design system & redesign | C6: Figma design system and screens, then the web app restyled to match them | D6: Done so far | F6: =COUNTIFS(Backlog!$E$2:$E$500,$A6,Backlog!$J$2:$J$500,"<>Won't do") | G6: =COUNTIFS(Backlog!$E$2:$E$500,$A6,Backlog!$J$2:$J$500,"Done") | H6: =COUNTIFS(Backlog!$E$2:$E$500,$A6,Backlog!$J$2:$J$500,"In progress") | I6: =COUNTIFS(Backlog!$E$2:$E$500,$A6,Backlog!$J$2:$J$500,"Blocked") | J6: =F6-G6 | K6: =IF(F6=0,0,G6/F6) | L6: =IF(F6=0,"Empty",IF(G6=F6,"Done",IF(G6+H6+I6>0,"In progress","Not started")))
A7: M9 | B7: Insights | C7: Analytics and Interview ready: APIs and pages | D7: Done so far | F7: =COUNTIFS(Backlog!$E$2:$E$500,$A7,Backlog!$J$2:$J$500,"<>Won't do") | G7: =COUNTIFS(Backlog!$E$2:$E$500,$A7,Backlog!$J$2:$J$500,"Done") | H7: =COUNTIFS(Backlog!$E$2:$E$500,$A7,Backlog!$J$2:$J$500,"In progress") | I7: =COUNTIFS(Backlog!$E$2:$E$500,$A7,Backlog!$J$2:$J$500,"Blocked") | J7: =F7-G7 | K7: =IF(F7=0,0,G7/F7) | L7: =IF(F7=0,"Empty",IF(G7=F7,"Done",IF(G7+H7+I7>0,"In progress","Not started")))
A8: M1 | B8: Web: core study loop | C8: A learner can find a path, enroll, study and manage it entirely from the web app | D8: Done so far | F8: =COUNTIFS(Backlog!$E$2:$E$500,$A8,Backlog!$J$2:$J$500,"<>Won't do") | G8: =COUNTIFS(Backlog!$E$2:$E$500,$A8,Backlog!$J$2:$J$500,"Done") | H8: =COUNTIFS(Backlog!$E$2:$E$500,$A8,Backlog!$J$2:$J$500,"In progress") | I8: =COUNTIFS(Backlog!$E$2:$E$500,$A8,Backlog!$J$2:$J$500,"Blocked") | J8: =F8-G8 | K8: =IF(F8=0,0,G8/F8) | L8: =IF(F8=0,"Empty",IF(G8=F8,"Done",IF(G8+H8+I8>0,"In progress","Not started")))
A9: M2 | B9: Production launch | C9: CI, deployment and monitoring so the app can run for real users | D9: Next | F9: =COUNTIFS(Backlog!$E$2:$E$500,$A9,Backlog!$J$2:$J$500,"<>Won't do") | G9: =COUNTIFS(Backlog!$E$2:$E$500,$A9,Backlog!$J$2:$J$500,"Done") | H9: =COUNTIFS(Backlog!$E$2:$E$500,$A9,Backlog!$J$2:$J$500,"In progress") | I9: =COUNTIFS(Backlog!$E$2:$E$500,$A9,Backlog!$J$2:$J$500,"Blocked") | J9: =F9-G9 | K9: =IF(F9=0,0,G9/F9) | L9: =IF(F9=0,"Empty",IF(G9=F9,"Done",IF(G9+H9+I9>0,"In progress","Not started")))
A10: M3 | B10: Email & accounts | C10: Email provider plus everything that needs email codes | D10: Done so far | F10: =COUNTIFS(Backlog!$E$2:$E$500,$A10,Backlog!$J$2:$J$500,"<>Won't do") | G10: =COUNTIFS(Backlog!$E$2:$E$500,$A10,Backlog!$J$2:$J$500,"Done") | H10: =COUNTIFS(Backlog!$E$2:$E$500,$A10,Backlog!$J$2:$J$500,"In progress") | I10: =COUNTIFS(Backlog!$E$2:$E$500,$A10,Backlog!$J$2:$J$500,"Blocked") | J10: =F10-G10 | K10: =IF(F10=0,0,G10/F10) | L10: =IF(F10=0,"Empty",IF(G10=F10,"Done",IF(G10+H10+I10>0,"In progress","Not started")))
A11: M4 | B11: Teams & creators (web) | C11: Web screens for organizations, building your own paths, admin and moderation | D11: Done so far | F11: =COUNTIFS(Backlog!$E$2:$E$500,$A11,Backlog!$J$2:$J$500,"<>Won't do") | G11: =COUNTIFS(Backlog!$E$2:$E$500,$A11,Backlog!$J$2:$J$500,"Done") | H11: =COUNTIFS(Backlog!$E$2:$E$500,$A11,Backlog!$J$2:$J$500,"In progress") | I11: =COUNTIFS(Backlog!$E$2:$E$500,$A11,Backlog!$J$2:$J$500,"Blocked") | J11: =F11-G11 | K11: =IF(F11=0,0,G11/F11) | L11: =IF(F11=0,"Empty",IF(G11=F11,"Done",IF(G11+H11+I11>0,"In progress","Not started")))
A12: M5 | B12: Engagement & scale | C12: Reminders, export, pagination and performance as usage grows | D12: Later | F12: =COUNTIFS(Backlog!$E$2:$E$500,$A12,Backlog!$J$2:$J$500,"<>Won't do") | G12: =COUNTIFS(Backlog!$E$2:$E$500,$A12,Backlog!$J$2:$J$500,"Done") | H12: =COUNTIFS(Backlog!$E$2:$E$500,$A12,Backlog!$J$2:$J$500,"In progress") | I12: =COUNTIFS(Backlog!$E$2:$E$500,$A12,Backlog!$J$2:$J$500,"Blocked") | J12: =F12-G12 | K12: =IF(F12=0,0,G12/F12) | L12: =IF(F12=0,"Empty",IF(G12=F12,"Done",IF(G12+H12+I12>0,"In progress","Not started")))
A13: M6 | B13: Quality & docs | C13: Stronger tests and documentation | D13: Ongoing | F13: =COUNTIFS(Backlog!$E$2:$E$500,$A13,Backlog!$J$2:$J$500,"<>Won't do") | G13: =COUNTIFS(Backlog!$E$2:$E$500,$A13,Backlog!$J$2:$J$500,"Done") | H13: =COUNTIFS(Backlog!$E$2:$E$500,$A13,Backlog!$J$2:$J$500,"In progress") | I13: =COUNTIFS(Backlog!$E$2:$E$500,$A13,Backlog!$J$2:$J$500,"Blocked") | J13: =F13-G13 | K13: =IF(F13=0,0,G13/F13) | L13: =IF(F13=0,"Empty",IF(G13=F13,"Done",IF(G13+H13+I13>0,"In progress","Not started")))
A14: M7 | B14: Mobile app | C14: A mobile app on the same API and schemas | D14: Later | F14: =COUNTIFS(Backlog!$E$2:$E$500,$A14,Backlog!$J$2:$J$500,"<>Won't do") | G14: =COUNTIFS(Backlog!$E$2:$E$500,$A14,Backlog!$J$2:$J$500,"Done") | H14: =COUNTIFS(Backlog!$E$2:$E$500,$A14,Backlog!$J$2:$J$500,"In progress") | I14: =COUNTIFS(Backlog!$E$2:$E$500,$A14,Backlog!$J$2:$J$500,"Blocked") | J14: =F14-G14 | K14: =IF(F14=0,0,G14/F14) | L14: =IF(F14=0,"Empty",IF(G14=F14,"Done",IF(G14+H14+I14>0,"In progress","Not started")))
A15: M10 | B15: Platform admin | C15: Superadmin tools to run the platform: users, an overview, organizations and an audit log | D15: Next | F15: =COUNTIFS(Backlog!$E$2:$E$500,$A15,Backlog!$J$2:$J$500,"<>Won't do") | G15: =COUNTIFS(Backlog!$E$2:$E$500,$A15,Backlog!$J$2:$J$500,"Done") | H15: =COUNTIFS(Backlog!$E$2:$E$500,$A15,Backlog!$J$2:$J$500,"In progress") | I15: =COUNTIFS(Backlog!$E$2:$E$500,$A15,Backlog!$J$2:$J$500,"Blocked") | J15: =F15-G15 | K15: =IF(F15=0,0,G15/F15) | L15: =IF(F15=0,"Empty",IF(G15=F15,"Done",IF(G15+H15+I15>0,"In progress","Not started")))
A16: M11 | B16: Launch & growth | C16: The first users: official paths to study, outreach, feedback and the numbers that show what works | D16: Next | F16: =COUNTIFS(Backlog!$E$2:$E$500,$A16,Backlog!$J$2:$J$500,"<>Won't do") | G16: =COUNTIFS(Backlog!$E$2:$E$500,$A16,Backlog!$J$2:$J$500,"Done") | H16: =COUNTIFS(Backlog!$E$2:$E$500,$A16,Backlog!$J$2:$J$500,"In progress") | I16: =COUNTIFS(Backlog!$E$2:$E$500,$A16,Backlog!$J$2:$J$500,"Blocked") | J16: =F16-G16 | K16: =IF(F16=0,0,G16/F16) | L16: =IF(F16=0,"Empty",IF(G16=F16,"Done",IF(G16+H16+I16>0,"In progress","Not started")))
A17: Total | F17: =SUM(F5:F16) | G17: =SUM(G5:G16) | H17: =SUM(H5:H16) | I17: =SUM(I5:I16) | J17: =SUM(J5:J16) | K17: =IF(F17=0,0,G17/F17)

Sheet Backlog
A1: ID | B1: Title | C1: Description | D1: Area | E1: Milestone | F1: Milestone name | G1: Type | H1: Priority | I1: Size | J1: Status | K1: Depends on | L1: Owner | M1: Target date | N1: Done date | O1: Source | P1: Notes
A2: SL-001 | B2: Monorepo, API and shared packages | C2: Turborepo + Yarn workspaces; NestJS API; schemas, casl, database, logger, nestjs packages | D2: Backend | E2: M0 | F2: =IFERROR(INDEX(Roadmap!$B$5:$B$16,MATCH(E2,Roadmap!$A$5:$A$16,0)),"") | G2: Feature | H2: P1 | I2: XL | J2: Done | N2: 46290 | O2: README roadmap
A3: SL-002 | B3: Organizations, accounts and moderation API | C3: Organization management, account settings, path reports and moderation | D3: Backend | E3: M0 | F3: =IFERROR(INDEX(Roadmap!$B$5:$B$16,MATCH(E3,Roadmap!$A$5:$A$16,0)),"") | G3: Feature | H3: P1 | I3: L | J3: Done | N3: 46290 | O3: README roadmap
A4: SL-003 | B4: Migration CLI | C4: migration:generate/run/revert/show via nest-commander | D4: Tooling | E4: M0 | F4: =IFERROR(INDEX(Roadmap!$B$5:$B$16,MATCH(E4,Roadmap!$A$5:$A$16,0)),"") | G4: Feature | H4: P1 | I4: M | J4: Done | N4: 46290 | O4: README roadmap
A5: SL-004 | B5: Unit tests, 100% coverage and mutation testing | C5: Vitest everywhere, combined coverage report, Stryker | D5: Testing | E5: M0 | F5: =IFERROR(INDEX(Roadmap!$B$5:$B$16,MATCH(E5,Roadmap!$A$5:$A$16,0)),"") | G5: Chore | H5: P1 | I5: L | J5: Done | N5: 46291 | O5: README roadmap
A6: SL-005 | B6: Web app with homepage, login and session handling | C6: React + Vite app, API client, session restored from refresh cookie | D6: Frontend | E6: M0 | F6: =IFERROR(INDEX(Roadmap!$B$5:$B$16,MATCH(E6,Roadmap!$A$5:$A$16,0)),"") | G6: Feature | H6: P1 | I6: M | J6: Done | N6: 46291 | O6: README roadmap
A7: SL-006 | B7: Signup page | C7: /signup with client-side checks and API errors on fields | D7: Frontend | E7: M0 | F7: =IFERROR(INDEX(Roadmap!$B$5:$B$16,MATCH(E7,Roadmap!$A$5:$A$16,0)),"") | G7: Feature | H7: P1 | I7: S | J7: Done | N7: 46293 | O7: README roadmap
A8: SL-007 | B8: Automatic access-token renewal | C8: Retry once after POST /auth/refresh on a 401 with WWW-Authenticate: Bearer | D8: Frontend | E8: M0 | F8: =IFERROR(INDEX(Roadmap!$B$5:$B$16,MATCH(E8,Roadmap!$A$5:$A$16,0)),"") | G8: Feature | H8: P1 | I8: S | J8: Done | N8: 46294 | O8: README roadmap
A9: SL-008 | B9: db:seed dummy data | C9: Users, organizations, catalog, enrollments, progress and a month of sessions | D9: Tooling | E9: M0 | F9: =IFERROR(INDEX(Roadmap!$B$5:$B$16,MATCH(E9,Roadmap!$A$5:$A$16,0)),"") | G9: Feature | H9: P2 | I9: M | J9: Done | N9: 46294 | O9: README roadmap
A10: SL-009 | B10: Dashboard at /app | C10: Stats, streak, last 30 days, paths with progress, recent sessions | D10: Frontend | E10: M0 | F10: =IFERROR(INDEX(Roadmap!$B$5:$B$16,MATCH(E10,Roadmap!$A$5:$A$16,0)),"") | G10: Feature | H10: P1 | I10: M | J10: Done | N10: 46294 | O10: README roadmap
A11: SL-010 | B11: Study sessions page at /app/sessions | C11: History by day; log, edit and delete sessions | D11: Frontend | E11: M0 | F11: =IFERROR(INDEX(Roadmap!$B$5:$B$16,MATCH(E11,Roadmap!$A$5:$A$16,0)),"") | G11: Feature | H11: P1 | I11: M | J11: Done | N11: 46294 | O11: README roadmap
A12: SL-011 | B12: Learning path page at /app/paths/:id | C12: Progress at every level, item status, notes and exercises, log time | D12: Frontend | E12: M0 | F12: =IFERROR(INDEX(Roadmap!$B$5:$B$16,MATCH(E12,Roadmap!$A$5:$A$16,0)),"") | G12: Feature | H12: P1 | I12: M | J12: Done | N12: 46314 | O12: README roadmap
A13: SL-012 | B13: Catalog page | C13: Browse paths you can see (GET /catalog/paths); filter by source (official, mine, organizations, community) and search | D13: Frontend | E13: M1 | F13: =IFERROR(INDEX(Roadmap!$B$5:$B$16,MATCH(E13,Roadmap!$A$5:$A$16,0)),"") | G13: Feature | H13: P1 | I13: M | J13: Done | N13: 46314 | O13: README roadmap
A14: SL-013 | B14: Path preview before enrolling | C14: GET /catalog/paths/:pathId: modules, topics and items of a path, with an Enroll button | D14: Frontend | E14: M1 | F14: =IFERROR(INDEX(Roadmap!$B$5:$B$16,MATCH(E14,Roadmap!$A$5:$A$16,0)),"") | G14: Feature | H14: P1 | I14: M | J14: Done | K14: SL-012 | N14: 46318 | O14: README roadmap
A15: SL-014 | B15: Enroll in a path, optionally choosing parts | C15: POST /me/enrollments with include/exclude rules (e.g. "Arrays, but not Hashing") | D15: Frontend | E15: M1 | F15: =IFERROR(INDEX(Roadmap!$B$5:$B$16,MATCH(E15,Roadmap!$A$5:$A$16,0)),"") | G15: Feature | H15: P1 | I15: L | J15: Done | K15: SL-013 | N15: 46318 | O15: README roadmap
A16: SL-015 | B16: Manage an enrollment | C16: Pause, resume, drop (PATCH status), unenroll, edit rules (PUT .../rules) from the path page | D16: Frontend | E16: M1 | F16: =IFERROR(INDEX(Roadmap!$B$5:$B$16,MATCH(E16,Roadmap!$A$5:$A$16,0)),"") | G16: Feature | H16: P1 | I16: M | J16: Done | K16: SL-014 | N16: 46318 | O16: Proposed
A17: SL-016 | B17: Custom order in a path | C17: Reorder modules, topics and items (PUT .../orders/...), and reset to the admin order | D17: Frontend | E17: M1 | F17: =IFERROR(INDEX(Roadmap!$B$5:$B$16,MATCH(E17,Roadmap!$A$5:$A$16,0)),"") | G17: Feature | H17: P2 | I17: M | J17: Done | N17: 46318 | O17: Proposed
A18: SL-017 | B18: Reorder paths on the dashboard | C18: Drag or move paths; PUT /me/enrollments/order | D18: Frontend | E18: M1 | F18: =IFERROR(INDEX(Roadmap!$B$5:$B$16,MATCH(E18,Roadmap!$A$5:$A$16,0)),"") | G18: Feature | H18: P3 | I18: S | J18: Done | N18: 46318 | O18: Proposed
A19: SL-018 | B19: Account settings page | C19: Edit name (PATCH /auth/me), change password, delete account | D19: Frontend | E19: M1 | F19: =IFERROR(INDEX(Roadmap!$B$5:$B$16,MATCH(E19,Roadmap!$A$5:$A$16,0)),"") | G19: Feature | H19: P2 | I19: M | J19: Done | N19: 46318 | O19: Proposed
A20: SL-019 | B20: Update README intro | C20: Top of README still says apps/web is "empty for now" | D20: Docs | E20: M1 | F20: =IFERROR(INDEX(Roadmap!$B$5:$B$16,MATCH(E20,Roadmap!$A$5:$A$16,0)),"") | G20: Chore | H20: P3 | I20: XS | J20: Done | N20: 46318 | O20: Proposed
A21: SL-020 | B21: CI with GitHub Actions | C21: On every push/PR: build, lint, yarn test:cov, migration:generate --check, incremental mutation testing | D21: DevOps | E21: M2 | F21: =IFERROR(INDEX(Roadmap!$B$5:$B$16,MATCH(E21,Roadmap!$A$5:$A$16,0)),"") | G21: Chore | H21: P1 | I21: M | J21: Done | N21: 46319 | O21: README roadmap | P21: PRs only: lint, build, unit tests with coverage (posted on the PR) and the Playwright UI tests; turbo and Playwright caching. migration:generate --check and mutation testing moved to SL-080.
A22: SL-021 | B22: Branch protection on master | C22: PRs only, CI must pass, no force pushes (needs GitHub Pro or a public repo) | D22: DevOps | E22: M2 | F22: =IFERROR(INDEX(Roadmap!$B$5:$B$16,MATCH(E22,Roadmap!$A$5:$A$16,0)),"") | G22: Chore | H22: P2 | I22: XS | J22: Done | K22: SL-020 | N22: 46321 | O22: README roadmap | P22: Ruleset (branchruleset.json) active on master, checked through the GitHub API on 2026-10-26: no deletion, no force pushes, PRs only, both CI checks required.
A23: SL-022 | B23: Pre-commit hooks | C23: husky + lint-staged: lint and related tests on committed files | D23: DevOps | E23: M2 | F23: =IFERROR(INDEX(Roadmap!$B$5:$B$16,MATCH(E23,Roadmap!$A$5:$A$16,0)),"") | G23: Chore | H23: P2 | I23: S | J23: Not started | O23: README roadmap
A24: SL-023 | B24: Dockerfile and deployment | C24: Container images, migration:run as a release step | D24: DevOps | E24: M2 | F24: =IFERROR(INDEX(Roadmap!$B$5:$B$16,MATCH(E24,Roadmap!$A$5:$A$16,0)),"") | G24: Feature | H24: P1 | I24: L | J24: Done | N24: 46319 | O24: README roadmap | P24: Images built by GitHub Actions to GHCR; deployed on Civo k3s (deploy/civo), live at https://gradiaqo.com. Migrations run in an init container before the API starts.
A25: SL-024 | B25: Check production settings | C25: NODE_ENV=production, COOKIE_SECURE=true, SWAGGER_ENABLED=false, LOG_PRETTY=false, TRUST_PROXY | D25: DevOps | E25: M2 | F25: =IFERROR(INDEX(Roadmap!$B$5:$B$16,MATCH(E25,Roadmap!$A$5:$A$16,0)),"") | G25: Chore | H25: P1 | I25: S | J25: Done | K25: SL-023 | N25: 46319 | O25: README roadmap | P25: deploy/k8s/config.env: production, secure cookies, Swagger off, TRUST_PROXY=2 (Traefik + Caddy). SMTP on port 2525: Civo blocks 25/465/587.
A26: SL-025 | B26: Dependency updates and audit | C26: Dependabot or Renovate; yarn npm audit in CI | D26: DevOps | E26: M2 | F26: =IFERROR(INDEX(Roadmap!$B$5:$B$16,MATCH(E26,Roadmap!$A$5:$A$16,0)),"") | G26: Chore | H26: P2 | I26: S | J26: Not started | K26: SL-020 | O26: README roadmap
A27: SL-026 | B27: Error tracking | C27: e.g. Sentry for API and web | D27: Operations | E27: M2 | F27: =IFERROR(INDEX(Roadmap!$B$5:$B$16,MATCH(E27,Roadmap!$A$5:$A$16,0)),"") | G27: Feature | H27: P1 | I27: S | J27: Not started | K27: SL-023 | O27: README roadmap
A28: SL-027 | B28: Graceful shutdown | C28: Close database connections cleanly on deploy | D28: Operations | E28: M2 | F28: =IFERROR(INDEX(Roadmap!$B$5:$B$16,MATCH(E28,Roadmap!$A$5:$A$16,0)),"") | G28: Chore | H28: P2 | I28: S | J28: Not started | O28: README roadmap
A29: SL-028 | B29: Metrics | C29: Request counts, latency, database timing | D29: Operations | E29: M2 | F29: =IFERROR(INDEX(Roadmap!$B$5:$B$16,MATCH(E29,Roadmap!$A$5:$A$16,0)),"") | G29: Feature | H29: P3 | I29: M | J29: Not started | K29: SL-023 | O29: README roadmap
A30: SL-029 | B30: Rate limits in a shared store | C30: Move counters from memory to e.g. Redis before running more than one API instance | D30: Backend | E30: M2 | F30: =IFERROR(INDEX(Roadmap!$B$5:$B$16,MATCH(E30,Roadmap!$A$5:$A$16,0)),"") | G30: Chore | H30: P2 | I30: M | J30: Not started | O30: README roadmap
A31: SL-030 | B31: Set up an email provider | C31: Resend, SendGrid or Amazon SES; SMTP for development | D31: Backend | E31: M3 | F31: =IFERROR(INDEX(Roadmap!$B$5:$B$16,MATCH(E31,Roadmap!$A$5:$A$16,0)),"") | G31: Feature | H31: P1 | I31: M | J31: Done | N31: 46318 | O31: README roadmap
A32: SL-031 | B32: Email verification at signup | C32: OTP/code sent at signup; API + web screen | D32: Backend | E32: M3 | F32: =IFERROR(INDEX(Roadmap!$B$5:$B$16,MATCH(E32,Roadmap!$A$5:$A$16,0)),"") | G32: Feature | H32: P1 | I32: M | J32: Done | K32: SL-030 | N32: 46318 | O32: README roadmap
A33: SL-032 | B33: Password reset | C33: Forgot-password flow; API + web pages | D33: Backend | E33: M3 | F33: =IFERROR(INDEX(Roadmap!$B$5:$B$16,MATCH(E33,Roadmap!$A$5:$A$16,0)),"") | G33: Feature | H33: P1 | I33: M | J33: Done | K33: SL-030 | N33: 46318 | O33: README roadmap
A34: SL-033 | B34: Change your email | C34: Verify the new address before switching | D34: Backend | E34: M3 | F34: =IFERROR(INDEX(Roadmap!$B$5:$B$16,MATCH(E34,Roadmap!$A$5:$A$16,0)),"") | G34: Feature | H34: P2 | I34: M | J34: Done | K34: SL-030 | N34: 46318 | O34: README roadmap
A35: SL-034 | B35: Send invitation emails | C35: Today invited people only see them in GET /me/invitations | D35: Backend | E35: M3 | F35: =IFERROR(INDEX(Roadmap!$B$5:$B$16,MATCH(E35,Roadmap!$A$5:$A$16,0)),"") | G35: Feature | H35: P2 | I35: S | J35: Done | K35: SL-030 | N35: 46318 | O35: README roadmap | P35: Accepting invitations in the web app comes with SL-036
A36: SL-035 | B36: Organizations page | C36: Create, rename and delete organizations; members and roles; leave | D36: Frontend | E36: M4 | F36: =IFERROR(INDEX(Roadmap!$B$5:$B$16,MATCH(E36,Roadmap!$A$5:$A$16,0)),"") | G36: Feature | H36: P2 | I36: L | J36: Done | N36: 46318 | O36: Proposed
A37: SL-036 | B37: Invitations in the web app | C37: Owners/admins invite and revoke; users accept or decline (GET /me/invitations) | D37: Frontend | E37: M4 | F37: =IFERROR(INDEX(Roadmap!$B$5:$B$16,MATCH(E37,Roadmap!$A$5:$A$16,0)),"") | G37: Feature | H37: P2 | I37: M | J37: Done | K37: SL-035 | N37: 46318 | O37: Proposed
A38: SL-037 | B38: Build your own learning paths | C38: Create paths, modules, topics and items in your workspace; reorder; private/public | D38: Frontend | E38: M4 | F38: =IFERROR(INDEX(Roadmap!$B$5:$B$16,MATCH(E38,Roadmap!$A$5:$A$16,0)),"") | G38: Feature | H38: P2 | I38: XL | J38: Done | N38: 46314 | O38: Proposed
A39: SL-038 | B39: Link global items into your paths | C39: Search GET /catalog/items and link published items into your topics | D39: Frontend | E39: M4 | F39: =IFERROR(INDEX(Roadmap!$B$5:$B$16,MATCH(E39,Roadmap!$A$5:$A$16,0)),"") | G39: Feature | H39: P3 | I39: M | J39: Done | K39: SL-037 | N39: 46314 | O39: Proposed
A40: SL-039 | B40: Report a public path | C40: POST /catalog/paths/:pathId/reports from the catalog | D40: Frontend | E40: M4 | F40: =IFERROR(INDEX(Roadmap!$B$5:$B$16,MATCH(E40,Roadmap!$A$5:$A$16,0)),"") | G40: Feature | H40: P3 | I40: S | J40: Done | K40: SL-013 | N40: 46318 | O40: Proposed
...

Sheet How to use
A1: How to use this tracker
A3: Roadmap | B3: Milestones in order. Item counts, % done and status are formulas over the Backlog sheet; fill in only Timeframe and Target (yellow).
A4: Backlog | B4: One row per piece of work. Change Status as you go, and add the Done date when you finish.
A5: Adding an item | B5: Type in the first empty row under the table: it grows automatically. Use the next ID (SL-0xx) and pick a Milestone (M0–M11).
A6: Edit freely | B6: Status, Priority, Size, Owner, Target date, Done date, Notes, Depends on.
A7: Formula column | B7: Milestone name is looked up from the Roadmap sheet; don't type in it.
A9: Status | B9: Not started · In progress · Blocked · Done · Won't do (Won't do is left out of the counts)
A10: Priority | B10: P1 = needed for the current milestone · P2 = should do · P3 = nice to have
A11: Size | B11: XS < half a day · S ≈ 1 day · M ≈ 2–3 days · L ≈ a week · XL = more than a week (rough guesses)
A12: Source | B12: README roadmap = from the Roadmap section of README.md. Proposed = suggested from what the API already supports but the web app doesn't show yet.
A13: Done dates | B13: For M0, taken from the git history.
A14: Figma design | B14: Source "Figma design" = from the design work. Screens: https://www.figma.com/design/OtHkuUtj5AK1MYZYgMEJRH (StudyLog – App Design).

Sheet Lists
A1: Status | B1: Priority | C1: Size | D1: Type | E1: Area
A2: Not started | B2: P1 | C2: XS | D2: Feature | E2: Frontend
A3: In progress | B3: P2 | C3: S | D3: Bug | E3: Backend
A4: Blocked | B4: P3 | C4: M | D4: Chore | E4: Mobile
A5: Done | C5: L | E5: Design
A6: Won't do | C6: XL | E6: Testing
E7: DevOps
E8: Operations
E9: Tooling
E10: Docs
E11: Content
E12: Marketing
